<?xml version="1.0"?>
<robot name="rapiro">

  <!-- BaseLink -->

  <link name="base_link"/>
  
  <joint name="base_fix" type="fixed">
    <parent link="base_link"/>
    <child link="body"/>
  </joint>
  
  <!-- Torso and Head -->

  <link name="body">
    <visual>
      <origin xyz="0 0 .02"/>
      <geometry>
        <mesh filename="package://rapiro_description/meshes/body.stl"/>
      </geometry>
      <material name="rapiro_white" />
    </visual>
    <visual>
      <origin xyz="-.065 0 .03"/>
      <geometry>
        <mesh filename="package://rapiro_description/meshes/backpack.stl"/>
      </geometry>
      <material name="rapiro_white" />
    </visual>
  </link>
  
  <joint name="waist_jnt" type="revolute">
    <parent link="body"/>
    <origin xyz="0 0 -.015" rpy="3.142 0 1.571"/>
    <child link="waist"/>
    <axis xyz="0 0 1"/>
    <limit effort="1000.0" lower=".175" upper="2.967" velocity="10"/>
  </joint>
  
  <link name="waist">
    <visual>
      <origin xyz="0 0 0" rpy="3.142 0 0" />
      <geometry>
        <mesh filename="package://rapiro_description/meshes/waist.stl"/>
      </geometry>
      <material name="rapiro_white" />
    </visual>
  </link>
  
  <joint name="head_jnt" type="revolute">
    <parent link="body"/>
    <origin xyz="0 0 .0375" rpy="0 0 -1.571"/>
    <child link="head"/>
    <axis xyz="0 0 1"/>
    <limit effort="1000.0" lower=".175" upper="2.967" velocity="10"/>
  </joint>
  
  <link name="head">
    <visual>
      <origin xyz="0 0 .055"/>
      <geometry>
        <mesh filename="package://rapiro_description/meshes/head.stl"/>
      </geometry>
      <material name="rapiro_white" />
    </visual>
  </link>
  
  <!-- Legs and Feet -->
  
  <joint name="r_foot_y_jnt" type="revolute">
    <parent link="waist"/>
    <origin xyz="0 .03 .015" rpy="0 0 -1.571"/>
    <child link="r_leg"/>
    <axis xyz="0 0 1"/>
    <limit effort="1000.0" lower=".873" upper="2.269" velocity="10"/>
  </joint>
  
  <link name="r_leg" />
  
  <joint name="r_foot_p_jnt" type="revolute">
    <parent link="r_leg"/>
    <origin xyz="0 0 .035" rpy="0 -1.571 0"/>
    <child link="r_foot"/>
    <axis xyz="0 0 1"/>
    <limit effort="1000.0" lower=".611" upper="2.269" velocity="10"/>
  </joint>
  
  <link name="r_foot">
    <visual>
      <geometry>
        <mesh filename="package://rapiro_description/meshes/r_foot.stl"/>
      </geometry>
      <material name="rapiro_white" />
    </visual>
  </link>
  
  <joint name="l_foot_y_jnt" type="revolute">
    <parent link="waist"/>
    <origin xyz="0 -.03 .015" rpy="0 0 -1.571"/>
    <child link="l_leg"/>
    <axis xyz="0 0 1"/>
    <limit effort="1000.0" lower=".873" upper="2.269" velocity="10"/>
  </joint>
  
  <link name="l_leg" />
  
  <joint name="l_foot_p_jnt" type="revolute">
    <parent link="l_leg"/>
    <origin xyz="0 0 .035" rpy="0 -1.571 0"/>
    <child link="l_foot"/>
    <axis xyz="0 0 1"/>
    <limit effort="1000.0" lower=".873" upper="2.531" velocity="10"/>
  </joint>
  
  <link name="l_foot">
    <visual>
      <geometry>
        <mesh filename="package://rapiro_description/meshes/l_foot.stl"/>
      </geometry>
      <material name="rapiro_white" />
    </visual>
  </link>
  
  <!-- Arms and Hands -->
  
  <joint name="r_shld_r_jnt" type="revolute">
    <parent link="body"/>
    <origin xyz="0 -.06 .0225" rpy="0 1.571 -1.571"/>
    <child link="r_shoulder"/>
    <axis xyz="0 0 1"/>
    <limit effort="1000.0" lower="0" upper="3.142" velocity="10"/>
  </joint>
  
  <link name="r_shoulder">
    <visual>
      <origin xyz="0 0 .02" />
      <geometry>
        <mesh filename="package://rapiro_description/meshes/shoulder.stl"/>
      </geometry>
      <material name="rapiro_white" />
    </visual>
  </link>
  
  <joint name="r_shld_p_jnt" type="revolute">
    <parent link="r_shoulder"/>
    <origin xyz="0 0 .0225" rpy="-1.571 -2.269 0"/>
    <child link="r_arm"/>
    <axis xyz="0 0 1"/>
    <limit effort="1000.0" lower=".436" upper="2.356" velocity="10"/>
  </joint>
  
  <link name="r_arm">
    <visual>
      <origin xyz="0 0 .004" />
      <geometry>
        <mesh filename="package://rapiro_description/meshes/r_arm.stl"/>
      </geometry>
      <material name="rapiro_white" />
    </visual>
  </link>
  
  <joint name="r_hand_jnt" type="revolute">
    <parent link="r_arm"/>
    <origin xyz=".0505 0 0" rpy="3.142 0 1.920"/>
    <child link="r_hand"/>
    <axis xyz="0 0 1"/>
    <limit effort="1000.0" lower=".960" upper="1.920" velocity="10"/>
  </joint>
  
  <link name="r_hand">
    <visual>
      <origin xyz="0 0 0" />
      <geometry>
        <mesh filename="package://rapiro_description/meshes/r_hand.stl"/>
      </geometry>
      <material name="rapiro_white" />
    </visual>
  </link>
  
  <joint name="l_shld_r_jnt" type="revolute">
    <parent link="body"/>
    <origin xyz="0 .06 .0225" rpy="0 -1.571 -1.571"/>
    <child link="l_shoulder"/>
    <axis xyz="0 0 1"/>
    <limit effort="1000.0" lower="0" upper="3.142" velocity="10"/>
  </joint>
  
  <link name="l_shoulder">
    <visual>
      <origin xyz="0 0 .02" />
      <geometry>
        <mesh filename="package://rapiro_description/meshes/shoulder.stl"/>
      </geometry>
      <material name="rapiro_white" />
    </visual>
  </link>
  
  <joint name="l_shld_p_jnt" type="revolute">
    <parent link="l_shoulder"/>
    <origin xyz="0 0 .0225" rpy="1.571 .873 0"/>
    <child link="l_arm"/>
    <axis xyz="0 0 1"/>
    <limit effort="1000.0" lower=".785" upper="2.705" velocity="10"/>
  </joint>
  
  <link name="l_arm">
    <visual>
      <origin xyz="0 0 .004" />
      <geometry>
        <mesh filename="package://rapiro_description/meshes/l_arm.stl"/>
      </geometry>
      <material name="rapiro_white" />
    </visual>
  </link>
  
  <joint name="l_hand_jnt" type="revolute">
    <parent link="l_arm"/>
    <origin xyz=".0505 0 0" rpy="3.142 0 .960"/>
    <child link="l_hand"/>
    <axis xyz="0 0 1"/>
    <limit effort="1000.0" lower=".960" upper="1.920" velocity="10"/>
  </joint>
  
  <link name="l_hand">
    <visual>
      <origin xyz="0 0 0" />
      <geometry>
        <mesh filename="package://rapiro_description/meshes/l_hand.stl"/>
      </geometry>
      <material name="rapiro_white" />
    </visual>
  </link>
  
  <!-- Sensor Frames -->
  
  <joint name="usr_fix" type="fixed">
    <parent link="head"/>
    <origin xyz=".065 0 .045"/>
    <child link="usr_frame"/>
  </joint>
  
  <link name="usr_frame"/>
  
  <material name="rapiro_white">
    <color rgba=".8 .8 .8 1.0"/>
  </material>
  
</robot>
